Workbook

Sheet Pivot  Tables
A3: Category | B3: Revenue by Product Category | E3: Shipping Type | F3: Sum of Purchase Amount (USD)
A4: Accessories | B4: 74200 | E4: 2-Day Shipping | F4: 38080
A5: Clothing | B5: 104264 | E5: Express | F5: 39067
A6: Footwear | B6: 36093 | E6: Free Shipping | F6: 40777
A7: Outerwear | B7: 18524 | E7: Next Day Air | F7: 37993
A8: Grand Total | B8: 233081 | E8: Standard | F8: 38233
E9: Store Pickup | F9: 38931
A10: Season | B10: Revenue by Season | E10: Grand Total | F10: 233081
A11: Fall | B11: 60018
A12: Spring | B12: 58679 | E12: Payment Method | F12: Sum of Purchase Amount (USD)
A13: Summer | B13: 55777 | E13: Bank Transfer | F13: 36544
A14: Winter | B14: 58607 | E14: Cash | F14: 40002
A15: Grand Total | B15: 233081 | E15: Credit Card | F15: 40310
E16: Debit Card | F16: 38742
A17: Discount Applied | B17: Revenue on Discount | E17: PayPal | F17: 40109
A18: No | B18: 133670 | E18: Venmo | F18: 37374
A19: Yes | B19: 99411 | E19: Grand Total | F19: 233081
A20: Grand Total | B20: 233081
A22: Review Rating | B22: Count of Purchases per Rating | E22: Frequency of Purchases | F22: Revenue by Purchase Frequency
A23: 2.5 | B23: 66 | E23: Annually | F23: 34419
A24: 2.6 | B24: 159 | E24: Bi-Weekly | F24: 33200
A25: 2.7 | B25: 154 | E25: Every 3 Months | F25: 35088
A26: 2.8 | B26: 136 | E26: Fortnightly | F26: 32007
A27: 2.9 | B27: 170 | E27: Monthly | F27: 32810
A28: 3 | B28: 162 | E28: Quarterly | F28: 33771
A29: 3.1 | B29: 157 | E29: Weekly | F29: 31786
A30: 3.2 | B30: 152 | E30: Grand Total | F30: 233081
A31: 3.3 | B31: 152
A32: 3.4 | B32: 182 | E32: Revenue by Different Age Group | F32: Gender
A33: 3.5 | B33: 156 | E33: Age Group | F33: Female | G33: Male | H33: Grand Total
A34: 3.6 | B34: 149 | E34: Adult | F34: 36770 | G34: 73201 | H34: 109971
A35: 3.7 | B35: 156 | E35: Senior | F35: 27885 | G35: 60595 | H35: 88480
A36: 3.8 | B36: 142 | E36: Young | F36: 10536 | G36: 24094 | H36: 34630
A37: 3.9 | B37: 163 | E37: Grand Total | F37: 75191 | G37: 157890 | H37: 233081
A38: 4 | B38: 181
A39: 4.1 | B39: 148 | E39: Previous Purchases | F39: Sum of Purchase Amount (USD)
A40: 4.2 | B40: 171 | E40: 1 | F40: 4853
A41: 4.3 | B41: 147 | E41: 2 | F41: 4344
A42: 4.4 | B42: 158 | E42: 3 | F42: 5329
A43: 4.5 | B43: 139 | E43: 4 | F43: 5576
...

Sheet Dashboards
G1: Customer Purchase Behaviour Dashboard

Sheet KPI Cards
H1: KPI Cards of Customer Purchase Behaviour

Sheet Insights
D1: Customer Shopping Purchase Behaviour Analysis
D3: Insight | E3: Finding | F3: Result
D4: Highest-Selling Category | E4: Clothing | F4: $ 84,500
D5: Top Customer Location | E5: California | F5: 312 orders
D6: Most Popular Payment Method | E6: Credit Card | F6: 1,245 orders
D7: Most Used Shipping Type | E7: Free Shipping | F7: 0.352
D8: Average Purchase Value | E8: Overall | F8: $ 60.25
D9: Highest Rated Product Category | E9: Footwear | F9: 4.4 / 5
D10: Top Spending Customer Segment | E10: Age 25-34, Female | F10: $ 68.10 avg.
D11: Most Preferred Size | E11: M | F11: 1,102 orders
D12: Discount Used | E12: Yes | F12: 0.435
D14: Recommandations:
D15: 1. Focus on high-performing categories such as Clothing to maintain strong sales performance.
D16: 2. Analyze customer demand in California and other high-performing locations to identify opportunities for further growth.
D17: 3. Monitor Free Shipping preference and ensure operational efficiency to improve order completion.
D18: 4. Maintain a smooth Credit Card payment experience to support customer convenience.
D19: 5. Retain high-value customers in the 25-34 Female segment through personalized offers and engagement.

Sheet Sheet5
A2: =AVERAGE(shopping_behavior_updated!F:F) -> 59.764359
A3: =COUNT(shopping_behavior_updated!A:A) -> 3900
A4: =AVERAGE(shopping_behavior_updated!K:K) -> 3.7499487
A5: =COUNTIF(shopping_behavior_updated!P:P,">1")/(COUNTA(shopping_behavior_updated!A:A)-1)*100 -> 97.871795
A6: =COUNTIF(shopping_behavior_updated!N:N,"Yes")/(COUNTA(shopping_behavior_updated!A:A)-1)*100 -> 43

Sheet shopping_behavior_updated
A1: Customer ID | B1: Age | C1: Gender | D1: Item Purchased | E1: Category | F1: Purchase Amount (USD) | G1: Location | H1: Size | I1: Color | J1: Season | K1: Review Rating | L1: Subscription Status | M1: Shipping Type | N1: Discount Applied | O1: Promo Code Used | P1: Previous Purchases | Q1: Payment Method | R1: Frequency of Purchases | S1: Age Group | T1: Revenue | U1: Subscription Flag
A2: 1 | B2: 55 | C2: Male | D2: Blouse | E2: Clothing | F2: 53 | G2: Kentucky | H2: L | I2: Gray | J2: Winter | K2: 3.1 | L2: Yes | M2: Express | N2: Yes | O2: Yes | P2: 14 | Q2: Venmo | R2: Fortnightly | S2: =IF(Table1[[#This Row],[Age]]<=25,"Young",IF(Table1[[#This Row],[Age]]<=50,"Adult","Senior")) -> Senior | T2: =Table1[[#This Row],[Purchase Amount (USD)]] -> 53 | U2: =IF(Table1[[#This Row],[Subscription Status]]="Yes",1,IF(Table1[[#This Row],[Subscription Status]]="No",0)) -> 1
A3: 2 | B3: 19 | C3: Male | D3: Sweater | E3: Clothing | F3: 64 | G3: Maine | H3: L | I3: Maroon | J3: Winter | K3: 3.1 | L3: Yes | M3: Express | N3: Yes | O3: Yes | P3: 2 | Q3: Cash | R3: Fortnightly | S3: =IF(Table1[[#This Row],[Age]]<=25,"Young",IF(Table1[[#This Row],[Age]]<=50,"Adult","Senior")) -> Young | T3: =Table1[[#This Row],[Purchase Amount (USD)]] -> 64 | U3: =IF(Table1[[#This Row],[Subscription Status]]="Yes",1,IF(Table1[[#This Row],[Subscription Status]]="No",0)) -> 1
A4: 3 | B4: 50 | C4: Male | D4: Jeans | E4: Clothing | F4: 73 | G4: Massachusetts | H4: S | I4: Maroon | J4: Spring | K4: 3.1 | L4: Yes | M4: Free Shipping | N4: Yes | O4: Yes | P4: 23 | Q4: Credit Card | R4: Weekly | S4: =IF(Table1[[#This Row],[Age]]<=25,"Young",IF(Table1[[#This Row],[Age]]<=50,"Adult","Senior")) -> Adult | T4: =Table1[[#This Row],[Purchase Amount (USD)]] -> 73 | U4: =IF(Table1[[#This Row],[Subscription Status]]="Yes",1,IF(Table1[[#This Row],[Subscription Status]]="No",0)) -> 1
A5: 4 | B5: 21 | C5: Male | D5: Sandals | E5: Footwear | F5: 90 | G5: Rhode Island | H5: M | I5: Maroon | J5: Spring | K5: 3.5 | L5: Yes | M5: Next Day Air | N5: Yes | O5: Yes | P5: 49 | Q5: PayPal | R5: Weekly | S5: =IF(Table1[[#This Row],[Age]]<=25,"Young",IF(Table1[[#This Row],[Age]]<=50,"Adult","Senior")) -> Young | T5: =Table1[[#This Row],[Purchase Amount (USD)]] -> 90 | U5: =IF(Table1[[#This Row],[Subscription Status]]="Yes",1,IF(Table1[[#This Row],[Subscription Status]]="No",0)) -> 1
A6: 5 | B6: 45 | C6: Male | D6: Blouse | E6: Clothing | F6: 49 | G6: Oregon | H6: M | I6: Turquoise | J6: Spring | K6: 2.7 | L6: Yes | M6: Free Shipping | N6: Yes | O6: Yes | P6: 31 | Q6: PayPal | R6: Annually | S6: =IF(Table1[[#This Row],[Age]]<=25,"Young",IF(Table1[[#This Row],[Age]]<=50,"Adult","Senior")) -> Adult | T6: =Table1[[#This Row],[Purchase Amount (USD)]] -> 49 | U6: =IF(Table1[[#This Row],[Subscription Status]]="Yes",1,IF(Table1[[#This Row],[Subscription Status]]="No",0)) -> 1
A7: 6 | B7: 46 | C7: Male | D7: Sneakers | E7: Footwear | F7: 20 | G7: Wyoming | H7: M | I7: White | J7: Summer | K7: 2.9 | L7: Yes | M7: Standard | N7: Yes | O7: Yes | P7: 14 | Q7: Venmo | R7: Weekly | S7: =IF(Table1[[#This Row],[Age]]<=25,"Young",IF(Table1[[#This Row],[Age]]<=50,"Adult","Senior")) -> Adult | T7: =Table1[[#This Row],[Purchase Amount (USD)]] -> 20 | U7: =IF(Table1[[#This Row],[Subscription Status]]="Yes",1,IF(Table1[[#This Row],[Subscription Status]]="No",0)) -> 1
A8: 7 | B8: 63 | C8: Male | D8: Shirt | E8: Clothing | F8: 85 | G8: Montana | H8: M | I8: Gray | J8: Fall | K8: 3.2 | L8: Yes | M8: Free Shipping | N8: Yes | O8: Yes | P8: 49 | Q8: Cash | R8: Quarterly | S8: =IF(Table1[[#This Row],[Age]]<=25,"Young",IF(Table1[[#This Row],[Age]]<=50,"Adult","Senior")) -> Senior | T8: =Table1[[#This Row],[Purchase Amount (USD)]] -> 85 | U8: =IF(Table1[[#This Row],[Subscription Status]]="Yes",1,IF(Table1[[#This Row],[Subscription Status]]="No",0)) -> 1
A9: 8 | B9: 27 | C9: Male | D9: Shorts | E9: Clothing | F9: 34 | G9: Louisiana | H9: L | I9: Charcoal | J9: Winter | K9: 3.2 | L9: Yes | M9: Free Shipping | N9: Yes | O9: Yes | P9: 19 | Q9: Credit Card | R9: Weekly | S9: =IF(Table1[[#This Row],[Age]]<=25,"Young",IF(Table1[[#This Row],[Age]]<=50,"Adult","Senior")) -> Adult | T9: =Table1[[#This Row],[Purchase Amount (USD)]] -> 34 | U9: =IF(Table1[[#This Row],[Subscription Status]]="Yes",1,IF(Table1[[#This Row],[Subscription Status]]="No",0)) -> 1
A10: 9 | B10: 26 | C10: Male | D10: Coat | E10: Outerwear | F10: 97 | G10: West Virginia | H10: L | I10: Silver | J10: Summer | K10: 2.6 | L10: Yes | M10: Express | N10: Yes | O10: Yes | P10: 8 | Q10: Venmo | R10: Annually | S10: =IF(Table1[[#This Row],[Age]]<=25,"Young",IF(Table1[[#This Row],[Age]]<=50,"Adult","Senior")) -> Adult | T10: =Table1[[#This Row],[Purchase Amount (USD)]] -> 97 | U10: =IF(Table1[[#This Row],[Subscription Status]]="Yes",1,IF(Table1[[#This Row],[Subscription Status]]="No",0)) -> 1
A11: 10 | B11: 57 | C11: Male | D11: Handbag | E11: Accessories | F11: 31 | G11: Missouri | H11: M | I11: Pink | J11: Spring | K11: 4.8 | L11: Yes | M11: 2-Day Shipping | N11: Yes | O11: Yes | P11: 4 | Q11: Cash | R11: Quarterly | S11: =IF(Table1[[#This Row],[Age]]<=25,"Young",IF(Table1[[#This Row],[Age]]<=50,"Adult","Senior")) -> Senior | T11: =Table1[[#This Row],[Purchase Amount (USD)]] -> 31 | U11: =IF(Table1[[#This Row],[Subscription Status]]="Yes",1,IF(Table1[[#This Row],[Subscription Status]]="No",0)) -> 1
A12: 11 | B12: 53 | C12: Male | D12: Shoes | E12: Footwear | F12: 34 | G12: Arkansas | H12: L | I12: Purple | J12: Fall | K12: 4.1 | L12: Yes | M12: Store Pickup | N12: Yes | O12: Yes | P12: 26 | Q12: Bank Transfer | R12: Bi-Weekly | S12: =IF(Table1[[#This Row],[Age]]<=25,"Young",IF(Table1[[#This Row],[Age]]<=50,"Adult","Senior")) -> Senior | T12: =Table1[[#This Row],[Purchase Amount (USD)]] -> 34 | U12: =IF(Table1[[#This Row],[Subscription Status]]="Yes",1,IF(Table1[[#This Row],[Subscription Status]]="No",0)) -> 1
A13: 12 | B13: 30 | C13: Male | D13: Shorts | E13: Clothing | F13: 68 | G13: Hawaii | H13: S | I13: Olive | J13: Winter | K13: 4.9 | L13: Yes | M13: Store Pickup | N13: Yes | O13: Yes | P13: 10 | Q13: Bank Transfer | R13: Fortnightly | S13: =IF(Table1[[#This Row],[Age]]<=25,"Young",IF(Table1[[#This Row],[Age]]<=50,"Adult","Senior")) -> Adult | T13: =Table1[[#This Row],[Purchase Amount (USD)]] -> 68 | U13: =IF(Table1[[#This Row],[Subscription Status]]="Yes",1,IF(Table1[[#This Row],[Subscription Status]]="No",0)) -> 1
... A3901: 3900 | B3901: 52 | C3901: Female | D3901: Handbag | E3901: Accessories | F3901: 81 | G3901: California | H3901: M | I3901: Beige | J3901: Spring | K3901: 3.1 | L3901: No | M3901: Store Pickup | N3901: No | O3901: No | P3901: 33 | Q3901: Venmo | R3901: Quarterly | S3901: =IF(Table1[[#This Row],[Age]]<=25,"Young",IF(Table1[[#This Row],[Age]]<=50,"Adult","Senior")) -> Senior | T3901: =Table1[[#This Row],[Purchase Amount (USD)]] -> 81 | U3901: =IF(Table1[[#This Row],[Subscription Status]]="Yes",1,IF(Table1[[#This Row],[Subscription Status]]="No",0)) -> 0
